<?xml version="1.0" ?>
<!-- =================================================================================== -->
<!-- |    This document was autogenerated by xacro from my_robot.urdf.xacro            | -->
<!-- |    EDITING THIS FILE BY HAND IS NOT RECOMMENDED                                 | -->
<!-- =================================================================================== -->
<robot name="my_robot">
  <material name="grey">
    <color rgba="0.5 0.5 0.5 1"/>
  </material>
  <material name="blue">
    <color rgba="0 0 0.5 1"/>
  </material>
  <link name="base_link">
    <visual>
      <geometry>
        <box size="0.4 0.4 0.1"/>
      </geometry>
      <origin rpy="0 0 0" xyz="0 0 0.05"/>
      <material name="grey"/>
    </visual>
    <collision>
      <geometry>
        <box size="0.4 0.4 0.1"/>
      </geometry>
      <origin rpy="0 0 0" xyz="0 0 0.05"/>
    </collision>
  </link>
  <link name="shoulder_link">
    <visual>
      <geometry>
        <cylinder length="0.5" radius="0.1"/>
      </geometry>
      <origin rpy="0 0 0" xyz="0 0 0.25"/>
      <material name="blue"/>
    </visual>
    <collision>
      <geometry>
        <box size="0.2 0.2 0.5"/>
      </geometry>
      <origin rpy="0 0 0" xyz="0 0 0.25"/>
    </collision>
  </link>
  <joint name="joint1" type="revolute">
    <parent link="base_link"/>
    <child link="shoulder_link"/>
    <origin rpy="0 0 0" xyz="0 0 0.1"/>
    <axis xyz="0 0 1"/>
    <limit effort="1000.00" lower="-3.14" upper="3.14" velocity="1.0"/>
  </joint>
  <link name="arm_link">
    <visual>
      <geometry>
        <cylinder length="0.6" radius="0.05"/>
      </geometry>
      <origin rpy="0 0 0" xyz="0 0 0.30"/>
      <material name="grey"/>
    </visual>
    <collision>
      <geometry>
        <box size="0.1 0.1 0.6"/>
      </geometry>
      <origin rpy="0 0 0" xyz="0 0 0.30"/>
    </collision>
  </link>
  <joint name="joint2" type="revolute">
    <parent link="shoulder_link"/>
    <child link="arm_link"/>
    <origin rpy="0 0 0" xyz="0 0 0.5"/>
    <axis xyz="0 1 0"/>
    <limit effort="01000.0" lower="0.0" upper="2.5" velocity="1.0"/>
  </joint>
  <link name="elbow_link">
    <visual>
      <geometry>
        <cylinder length="0.1" radius="0.05"/>
      </geometry>
      <origin rpy="0 0 0" xyz="0 0 0.05"/>
      <material name="blue"/>
    </visual>
    <collision>
      <geometry>
        <box size="0.1 0.1 0.1"/>
      </geometry>
      <origin rpy="0 0 0" xyz="0 0 0.05"/>
    </collision>
  </link>
  <joint name="joint3" type="revolute">
    <parent link="arm_link"/>
    <child link="elbow_link"/>
    <origin rpy="0 0 0" xyz="0 0 0.6"/>
    <axis xyz="0 1 0"/>
    <limit effort="1000.0" lower="0.0" upper="2.5" velocity="1.0"/>
  </joint>
  <link name="forearm_link">
    <visual>
      <geometry>
        <cylinder length="0.5" radius="0.05"/>
      </geometry>
      <origin rpy="0 0 0" xyz="0 0 0.25"/>
      <material name="grey"/>
    </visual>
    <collision>
      <geometry>
        <box size="0.1 0.1 0.5"/>
      </geometry>
      <origin rpy="0 0 0" xyz="0 0 0.25"/>
    </collision>
  </link>
  <joint name="joint4" type="revolute">
    <parent link="elbow_link"/>
    <child link="forearm_link"/>
    <origin rpy="0 0 0" xyz="0 0 0.1"/>
    <axis xyz="0 0 1"/>
    <limit effort="1000.00" lower="-3.14" upper="3.14" velocity="1.0"/>
  </joint>
  <link name="wrist_link">
    <visual>
      <geometry>
        <box size="0.1 0.1 0.05"/>
      </geometry>
      <origin rpy="0 0 0" xyz="0 0 0.025"/>
      <material name="blue"/>
    </visual>
    <collision>
      <geometry>
        <box size="0.1 0.1 0.05"/>
      </geometry>
      <origin rpy="0 0 0" xyz="0 0 0.025"/>
    </collision>
  </link>
  <joint name="joint5" type="revolute">
    <parent link="forearm_link"/>
    <child link="wrist_link"/>
    <origin rpy="0 0 0" xyz="0 0 0.5"/>
    <axis xyz="0 1 0"/>
    <limit effort="1000" lower="-1.57" upper="1.57" velocity="1"/>
  </joint>
  <link name="hand_link">
    <visual>
      <geometry>
        <box size="0.1 0.1 0.02"/>
      </geometry>
      <origin rpy="0 0 0" xyz="0 0 0.01"/>
      <material name="grey"/>
    </visual>
    <collision>
      <geometry>
        <box size="0.1 0.1 0.02"/>
      </geometry>
      <origin rpy="0 0 0" xyz="0 0 0.01"/>
    </collision>
  </link>
  <joint name="joint6" type="continuous">
    <parent link="wrist_link"/>
    <child link="hand_link"/>
    <origin rpy="0 0 0" xyz="0 0 0.05"/>
    <axis xyz="0 0 1"/>
  </joint>
  <link name="tool_link">
        


    </link>
  <joint name="hand_tool_joint" type="fixed">
    <parent link="hand_link"/>
    <child link="tool_link"/>
    <origin rpy="0 0 0" xyz="0 0 0.02"/>
  </joint>
</robot>
